Internal Server Error: /index/
Traceback (most recent call last):
  File "C:\Users\chanm\OneDrive\Desktop\ERP\backend\env\Lib\site-packages\django\core\handlers\exception.py", line 55, in inner
    response = get_response(request)
               ^^^^^^^^^^^^^^^^^^^^^
  File "C:\Users\chanm\OneDrive\Desktop\ERP\backend\env\Lib\site-packages\django\core\handlers\base.py", line 197, in _get_response
    response = wrapped_callback(request, *callback_args, **callback_kwargs)
               ^^^^^^^^^^^^^^^^^^^^^^^^^^^^^^^^^^^^^^^^^^^^^^^^^^^^^^^^^^^^
  File "C:\Users\chanm\OneDrive\Desktop\ERP\backend\authentication\views.py", line 44, in index
    return StudentLogin.msteams(request)
           ^^^^^^^^^^^^^^^^^^^^^^^^^^^^^
TypeError: StudentLogin.msteams() missing 1 required positional argument: 'request'
"GET /index/ HTTP/1.1" 500 73979
Internal Server Error: /index/
Traceback (most recent call last):
  File "C:\Users\chanm\OneDrive\Desktop\ERP\backend\env\Lib\site-packages\django\core\handlers\exception.py", line 55, in inner
    response = get_response(request)
               ^^^^^^^^^^^^^^^^^^^^^
  File "C:\Users\chanm\OneDrive\Desktop\ERP\backend\env\Lib\site-packages\django\core\handlers\base.py", line 197, in _get_response
    response = wrapped_callback(request, *callback_args, **callback_kwargs)
               ^^^^^^^^^^^^^^^^^^^^^^^^^^^^^^^^^^^^^^^^^^^^^^^^^^^^^^^^^^^^
  File "C:\Users\chanm\OneDrive\Desktop\ERP\backend\authentication\views.py", line 44, in index
    return StudentLogin().msteams(request)
           ^^^^^^^^^^^^^^^^^^^^^^^^^^^^^^^
  File "C:\Users\chanm\OneDrive\Desktop\ERP\backend\student\views.py", line 139, in msteams
    token = self.get_tokens_for_user(user)
        ^^^^^^^^^^^^^^^^^^^^^^^^^^^^^^
TypeError: StudentLogin.get_tokens_for_user() takes 1 positional argument but 2 were given
"GET /index/ HTTP/1.1" 500 79068
Internal Server Error: /index/
Traceback (most recent call last):
  File "C:\Users\chanm\OneDrive\Desktop\ERP\backend\env\Lib\site-packages\django\core\handlers\exception.py", line 55, in inner
    response = get_response(request)
               ^^^^^^^^^^^^^^^^^^^^^
  File "C:\Users\chanm\OneDrive\Desktop\ERP\backend\env\Lib\site-packages\django\core\handlers\base.py", line 197, in _get_response
    response = wrapped_callback(request, *callback_args, **callback_kwargs)
               ^^^^^^^^^^^^^^^^^^^^^^^^^^^^^^^^^^^^^^^^^^^^^^^^^^^^^^^^^^^^
  File "C:\Users\chanm\OneDrive\Desktop\ERP\backend\authentication\views.py", line 44, in index
    return StudentLogin().msteams(request)
           ^^^^^^^^^^^^^^^^^^^^^^^^^^^^^^^
  File "C:\Users\chanm\OneDrive\Desktop\ERP\backend\student\views.py", line 143, in msteams
    return Response(token.data, status=status.HTTP_200_OK)
                    ^^^^^^^^^^
AttributeError: 'dict' object has no attribute 'data'
"GET /index/ HTTP/1.1" 500 79361
Internal Server Error: /index/
Traceback (most recent call last):
  File "C:\Users\chanm\OneDrive\Desktop\ERP\backend\env\Lib\site-packages\django\core\handlers\exception.py", line 55, in inner
    response = get_response(request)
               ^^^^^^^^^^^^^^^^^^^^^
  File "C:\Users\chanm\OneDrive\Desktop\ERP\backend\env\Lib\site-packages\django\core\handlers\base.py", line 220, in _get_response
    response = response.render()
               ^^^^^^^^^^^^^^^^^
  File "C:\Users\chanm\OneDrive\Desktop\ERP\backend\env\Lib\site-packages\django\template\response.py", line 114, in render
    self.content = self.rendered_content
                   ^^^^^^^^^^^^^^^^^^^^^
  File "C:\Users\chanm\OneDrive\Desktop\ERP\backend\env\Lib\site-packages\rest_framework\response.py", line 55, in rendered_content
    assert renderer, ".accepted_renderer not set on Response"
AssertionError: .accepted_renderer not set on Response
"GET /index/ HTTP/1.1" 500 78192
You're accessing the development server over HTTPS, but it only supports HTTP.
You're accessing the development server over HTTPS, but it only supports HTTP.
You're accessing the development server over HTTPS, but it only supports HTTP.
You're accessing the development server over HTTPS, but it only supports HTTP.
You're accessing the development server over HTTPS, but it only supports HTTP.
You're accessing the development server over HTTPS, but it only supports HTTP.
You're accessing the development server over HTTPS, but it only supports HTTP.
You're accessing the development server over HTTPS, but it only supports HTTP.
Internal Server Error: /index/
Traceback (most recent call last):
  File "C:\Users\chanm\OneDrive\Desktop\ERP\backend\env\Lib\site-packages\django\core\handlers\exception.py", line 55, in inner
    response = get_response(request)
               ^^^^^^^^^^^^^^^^^^^^^
  File "C:\Users\chanm\OneDrive\Desktop\ERP\backend\env\Lib\site-packages\django\core\handlers\base.py", line 197, in _get_response
    response = wrapped_callback(request, *callback_args, **callback_kwargs)
               ^^^^^^^^^^^^^^^^^^^^^^^^^^^^^^^^^^^^^^^^^^^^^^^^^^^^^^^^^^^^
  File "C:\Users\chanm\OneDrive\Desktop\ERP\backend\env\Lib\site-packages\django\views\decorators\csrf.py", line 56, in wrapper_view
    return view_func(*args, **kwargs)
           ^^^^^^^^^^^^^^^^^^^^^^^^^^
  File "C:\Users\chanm\OneDrive\Desktop\ERP\backend\env\Lib\site-packages\django\views\generic\base.py", line 104, in view
    return self.dispatch(request, *args, **kwargs)
           ^^^^^^^^^^^^^^^^^^^^^^^^^^^^^^^^^^^^^^^
  File "C:\Users\chanm\OneDrive\Desktop\ERP\backend\env\Lib\site-packages\rest_framework\views.py", line 509, in dispatch
    response = self.handle_exception(exc)
               ^^^^^^^^^^^^^^^^^^^^^^^^^^
  File "C:\Users\chanm\OneDrive\Desktop\ERP\backend\env\Lib\site-packages\rest_framework\views.py", line 469, in handle_exception
    self.raise_uncaught_exception(exc)
  File "C:\Users\chanm\OneDrive\Desktop\ERP\backend\env\Lib\site-packages\rest_framework\views.py", line 480, in raise_uncaught_exception
    raise exc
  File "C:\Users\chanm\OneDrive\Desktop\ERP\backend\env\Lib\site-packages\rest_framework\views.py", line 506, in dispatch
    response = handler(request, *args, **kwargs)
               ^^^^^^^^^^^^^^^^^^^^^^^^^^^^^^^^^
  File "C:\Users\chanm\OneDrive\Desktop\ERP\backend\env\Lib\site-packages\rest_framework\decorators.py", line 50, in handler
    return func(*args, **kwargs)
           ^^^^^^^^^^^^^^^^^^^^^
  File "C:\Users\chanm\OneDrive\Desktop\ERP\backend\authentication\views.py", line 42, in index
    user = User.objects.get(user_id=request.identity_context_data.username)
           ^^^^^^^^^^^^^^^^^^^^^^^^^^^^^^^^^^^^^^^^^^^^^^^^^^^^^^^^^^^^^^^^
  File "C:\Users\chanm\OneDrive\Desktop\ERP\backend\env\Lib\site-packages\django\db\models\manager.py", line 87, in manager_method
    return getattr(self.get_queryset(), name)(*args, **kwargs)
           ^^^^^^^^^^^^^^^^^^^^^^^^^^^^^^^^^^^^^^^^^^^^^^^^^^^
  File "C:\Users\chanm\OneDrive\Desktop\ERP\backend\env\Lib\site-packages\django\db\models\query.py", line 637, in get
    raise self.model.DoesNotExist(
authentication.models.User.DoesNotExist: User matching query does not exist.
"GET /index/ HTTP/1.1" 500 114062
Internal Server Error: /auth/redirect
Traceback (most recent call last):
  File "C:\Users\chanm\OneDrive\Desktop\ERP\backend\env\Lib\site-packages\django\core\handlers\exception.py", line 55, in inner
    response = get_response(request)
               ^^^^^^^^^^^^^^^^^^^^^
  File "C:\Users\chanm\OneDrive\Desktop\ERP\backend\env\Lib\site-packages\django\core\handlers\base.py", line 197, in _get_response
    response = wrapped_callback(request, *callback_args, **callback_kwargs)
               ^^^^^^^^^^^^^^^^^^^^^^^^^^^^^^^^^^^^^^^^^^^^^^^^^^^^^^^^^^^^
  File "C:\Users\chanm\OneDrive\Desktop\ERP\backend\env\Lib\site-packages\ms_identity_web\django\msal_views_and_urls.py", line 39, in aad_redirect
    return self.ms_identity_web.process_auth_redirect(
           ^^^^^^^^^^^^^^^^^^^^^^^^^^^^^^^^^^^^^^^^^^^
  File "C:\Users\chanm\OneDrive\Desktop\ERP\backend\env\Lib\site-packages\ms_identity_web\__init__.py", line 40, in assert_adapter
    return f(self, *args, **kwargs)
           ^^^^^^^^^^^^^^^^^^^^^^^^
  File "C:\Users\chanm\OneDrive\Desktop\ERP\backend\env\Lib\site-packages\ms_identity_web\__init__.py", line 127, in process_auth_redirect
    raise ase
  File "C:\Users\chanm\OneDrive\Desktop\ERP\backend\env\Lib\site-packages\ms_identity_web\__init__.py", line 105, in process_auth_redirect
    self._verify_state(req_params)
  File "C:\Users\chanm\OneDrive\Desktop\ERP\backend\env\Lib\site-packages\ms_identity_web\__init__.py", line 40, in assert_adapter
    return f(self, *args, **kwargs)
           ^^^^^^^^^^^^^^^^^^^^^^^^
  File "C:\Users\chanm\OneDrive\Desktop\ERP\backend\env\Lib\site-packages\ms_identity_web\__init__.py", line 259, in _verify_state
    raise AuthSecurityError("Failed to match request state with session state")
ms_identity_web.errors.AuthSecurityError: Failed to match request state with session state
"GET /auth/redirect?code=0.AVYArapOG4e4z0iEB-mUIO2i-4ZbxlBpakVBorwhRfMbcAxWADk.AgABAAIAAAAtyolDObpQQ5VtlI4uGjEPAgDs_wUA9P86srWkRR2UMrByZSv5_khn1b_kgcrhDCka29uo1xuCXpyEEKoHTjbljIujW_jDadNmMMCx29yRjSAHz78-dkqf1fWQd2OPatvX0qNedmTkUeWTdGRhwLjYK65ztjpZvInDQb63ccKOsxUEXfwpjm1kUUk4A65j6OoxAnZUZckL3_eeB7bB0wpUXwezMGMNgEyBp2CxBZ5dFYv9sisoA7Za2ba6Fe-JL3jiD6y6u_VhKGxUzeQkon5cnBIkUe_TsKLdaTmLjy0eeUXRwjjtjoqdwiTx4JNbmLT-KC0V05vIMRlppqmRT1A36Zwf1-XZNgdeWaaXE--sdBc0aGo0IP4X8Rd2VjqXPqtaiX2f91HYS-w86ADLHWsbp9fdacD5bigYn1Anb_6JnEOEi1jtSoxtOmjpNK5z37aobXcHslqvNVfgBmnxgaBrm0sJw-lC1qxEfiSY-lh2wnBpbUViZsDPfqhyJj3lgWmV88EMjOy-EA6MRmZGs4bkD89j1ZotrbhOK_5IsY_RIFDHK8z_C2RCugjA0vs_h9V9Ssm0VSd1tmxH4wgqZB66NWefKUk2S6AmfjzHIkwEKrUyjgWzeAQA5Aj9x_R2AM72ZeqUS4fSpG_la6medHQH5TqCOjej99olX6AKKS4wSC7KoRSDL7ZXY2HQq7zQR8hbwwkFS3zkMHo_UxET_tCUl__pgsNbTW8GHgap5-QMN9D-zNGMhNzZ&state=3b10fa84-a75c-4f2a-8f2e-dadef31c6952&session_state=0eac7896-4461-41e8-91b1-c462ff48fba0 HTTP/1.1" 500 109212
Internal Server Error: /auth/redirect
Traceback (most recent call last):
  File "C:\Users\chanm\OneDrive\Desktop\ERP\backend\env\Lib\site-packages\django\core\handlers\exception.py", line 55, in inner
    response = get_response(request)
               ^^^^^^^^^^^^^^^^^^^^^
  File "C:\Users\chanm\OneDrive\Desktop\ERP\backend\env\Lib\site-packages\django\core\handlers\base.py", line 197, in _get_response
    response = wrapped_callback(request, *callback_args, **callback_kwargs)
               ^^^^^^^^^^^^^^^^^^^^^^^^^^^^^^^^^^^^^^^^^^^^^^^^^^^^^^^^^^^^
  File "C:\Users\chanm\OneDrive\Desktop\ERP\backend\env\Lib\site-packages\ms_identity_web\django\msal_views_and_urls.py", line 39, in aad_redirect
    return self.ms_identity_web.process_auth_redirect(
           ^^^^^^^^^^^^^^^^^^^^^^^^^^^^^^^^^^^^^^^^^^^
  File "C:\Users\chanm\OneDrive\Desktop\ERP\backend\env\Lib\site-packages\ms_identity_web\__init__.py", line 40, in assert_adapter
    return f(self, *args, **kwargs)
           ^^^^^^^^^^^^^^^^^^^^^^^^
  File "C:\Users\chanm\OneDrive\Desktop\ERP\backend\env\Lib\site-packages\ms_identity_web\__init__.py", line 127, in process_auth_redirect
    raise ase
  File "C:\Users\chanm\OneDrive\Desktop\ERP\backend\env\Lib\site-packages\ms_identity_web\__init__.py", line 105, in process_auth_redirect
    self._verify_state(req_params)
  File "C:\Users\chanm\OneDrive\Desktop\ERP\backend\env\Lib\site-packages\ms_identity_web\__init__.py", line 40, in assert_adapter
    return f(self, *args, **kwargs)
           ^^^^^^^^^^^^^^^^^^^^^^^^
  File "C:\Users\chanm\OneDrive\Desktop\ERP\backend\env\Lib\site-packages\ms_identity_web\__init__.py", line 259, in _verify_state
    raise AuthSecurityError("Failed to match request state with session state")
ms_identity_web.errors.AuthSecurityError: Failed to match request state with session state
"GET /auth/redirect?code=0.AVYArapOG4e4z0iEB-mUIO2i-4ZbxlBpakVBorwhRfMbcAxWADk.AgABAAIAAAAtyolDObpQQ5VtlI4uGjEPAgDs_wUA9P-zEhHdIjTj93LHX52a8OVmiiAHO-dOykZLOb7eka8A7EEa4yujpsfOHEQnhwwgTPse_iIcM1ODrjTRDghU-dagg77TtZ0rtWN3ZAaPa_f6fV3fzIEyYwVl70aFpaiYveBbMGHdNR7zmeHoWfK0SM5YhOb2r9nW5EPnj_C-aod54231yZ9b5832LbUIXOz_lPfyfMNjlwVm3RiWdZZi1psCOErmNZnVOQBoeYjtWMVAzOLv7j2uhCUY0O3fPGQfer4vrxUpxb0Tho9uJmjbJFQ1VUH9ooE9V1xRh6uVWUeagAMfCfErU0GivMKWnDVz4as-tLTIKuumkGdSgKd00wTSZhEHGv5qPQ8MCEJy_9NoiVAbXfp0uzerKA4oQWQXNjC96a8igWLj9l_yxKRbR5PXP4Ffxln3i0mnrIL4HoOJVqaxuZVgPKLvdNDiU7YkjnHytJTayqj3nMWzOdmHASbgFsgM2SbE0TIQ6GkC06-tHDSA-61Db0GquAyvHDvoWra_vBfgTqkrSYpFeZFzKe8R4vn1_XvkDy1Fs2NNVPUFcUAintxJWRFCcoxzYP3_eDxbdWd9aN9TtJsm8to1VxXsdAzKFzLCAsnU-_EeHfCR0V8UYCV6QwCYzsFm-ms3kIeLdGJIsHNI5bjYinYWQ82EcdgL6_ESmjrQXOD0KyQmpLCdlh7_RoH-dcDZ7MyxA1wjYRxt8sx0yQmkYFFZXY4&state=3b10fa84-a75c-4f2a-8f2e-dadef31c6952&session_state=0eac7896-4461-41e8-91b1-c462ff48fba0 HTTP/1.1" 500 109201
You're accessing the development server over HTTPS, but it only supports HTTP.
You're accessing the development server over HTTPS, but it only supports HTTP.
You're accessing the development server over HTTPS, but it only supports HTTP.
You're accessing the development server over HTTPS, but it only supports HTTP.
