Internal Server Error: /auth/student/login/
Traceback (most recent call last):
  File "C:\Users\chanm\OneDrive\Desktop\ERP\backend\myenv\Lib\site-packages\django\core\handlers\exception.py", line 55, in inner
    response = get_response(request)
               ^^^^^^^^^^^^^^^^^^^^^
  File "C:\Users\chanm\OneDrive\Desktop\ERP\backend\myenv\Lib\site-packages\django\core\handlers\base.py", line 197, in _get_response
    response = wrapped_callback(request, *callback_args, **callback_kwargs)
               ^^^^^^^^^^^^^^^^^^^^^^^^^^^^^^^^^^^^^^^^^^^^^^^^^^^^^^^^^^^^
  File "C:\Users\chanm\OneDrive\Desktop\ERP\backend\myenv\Lib\site-packages\django\views\decorators\csrf.py", line 54, in wrapped_view
    return view_func(*args, **kwargs)
           ^^^^^^^^^^^^^^^^^^^^^^^^^^
  File "C:\Users\chanm\OneDrive\Desktop\ERP\backend\myenv\Lib\site-packages\django\views\generic\base.py", line 103, in view
    return self.dispatch(request, *args, **kwargs)
           ^^^^^^^^^^^^^^^^^^^^^^^^^^^^^^^^^^^^^^^
  File "C:\Users\chanm\OneDrive\Desktop\ERP\backend\myenv\Lib\site-packages\rest_framework\views.py", line 509, in dispatch
    response = self.handle_exception(exc)
               ^^^^^^^^^^^^^^^^^^^^^^^^^^
  File "C:\Users\chanm\OneDrive\Desktop\ERP\backend\myenv\Lib\site-packages\rest_framework\views.py", line 469, in handle_exception
    self.raise_uncaught_exception(exc)
  File "C:\Users\chanm\OneDrive\Desktop\ERP\backend\myenv\Lib\site-packages\rest_framework\views.py", line 480, in raise_uncaught_exception
    raise exc
  File "C:\Users\chanm\OneDrive\Desktop\ERP\backend\myenv\Lib\site-packages\rest_framework\views.py", line 506, in dispatch
    response = handler(request, *args, **kwargs)
               ^^^^^^^^^^^^^^^^^^^^^^^^^^^^^^^^^
  File "C:\Users\chanm\OneDrive\Desktop\ERP\backend\AuthPortal\views\student_views.py", line 62, in post
    token = super().post(request, *args, **kwargs)
            ^^^^^^^^^^^^^^^^^^^^^^^^^^^^^^^^^^^^^^
  File "C:\Users\chanm\OneDrive\Desktop\ERP\backend\myenv\Lib\site-packages\rest_framework_simplejwt\views.py", line 44, in post
    serializer.is_valid(raise_exception=True)
  File "C:\Users\chanm\OneDrive\Desktop\ERP\backend\myenv\Lib\site-packages\rest_framework\serializers.py", line 227, in is_valid
    self._validated_data = self.run_validation(self.initial_data)
                           ^^^^^^^^^^^^^^^^^^^^^^^^^^^^^^^^^^^^^^
  File "C:\Users\chanm\OneDrive\Desktop\ERP\backend\myenv\Lib\site-packages\rest_framework\serializers.py", line 429, in run_validation
    value = self.validate(value)
            ^^^^^^^^^^^^^^^^^^^^
  File "C:\Users\chanm\OneDrive\Desktop\ERP\backend\myenv\Lib\site-packages\rest_framework_simplejwt\serializers.py", line 75, in validate
    refresh = self.get_token(self.user)
              ^^^^^^^^^^^^^^^^^^^^^^^^^
  File "C:\Users\chanm\OneDrive\Desktop\ERP\backend\myenv\Lib\site-packages\rest_framework_simplejwt\serializers.py", line 66, in get_token
    return cls.token_class.for_user(user)  # type: ignore
           ^^^^^^^^^^^^^^^^^^^^^^^^^^^^^^
  File "C:\Users\chanm\OneDrive\Desktop\ERP\backend\myenv\Lib\site-packages\rest_framework_simplejwt\tokens.py", line 203, in for_user
    user_id = getattr(user, api_settings.USER_ID_FIELD)
              ^^^^^^^^^^^^^^^^^^^^^^^^^^^^^^^^^^^^^^^^^
AttributeError: 'User' object has no attribute 'id'
"POST /auth/student/login/ HTTP/1.1" 500 119841
Internal Server Error: /auth/student/login/
Traceback (most recent call last):
  File "C:\Users\chanm\OneDrive\Desktop\ERP\backend\myenv\Lib\site-packages\django\core\handlers\exception.py", line 55, in inner
    response = get_response(request)
               ^^^^^^^^^^^^^^^^^^^^^
  File "C:\Users\chanm\OneDrive\Desktop\ERP\backend\myenv\Lib\site-packages\django\core\handlers\base.py", line 197, in _get_response
    response = wrapped_callback(request, *callback_args, **callback_kwargs)
               ^^^^^^^^^^^^^^^^^^^^^^^^^^^^^^^^^^^^^^^^^^^^^^^^^^^^^^^^^^^^
  File "C:\Users\chanm\OneDrive\Desktop\ERP\backend\myenv\Lib\site-packages\django\views\decorators\csrf.py", line 54, in wrapped_view
    return view_func(*args, **kwargs)
           ^^^^^^^^^^^^^^^^^^^^^^^^^^
  File "C:\Users\chanm\OneDrive\Desktop\ERP\backend\myenv\Lib\site-packages\django\views\generic\base.py", line 103, in view
    return self.dispatch(request, *args, **kwargs)
           ^^^^^^^^^^^^^^^^^^^^^^^^^^^^^^^^^^^^^^^
  File "C:\Users\chanm\OneDrive\Desktop\ERP\backend\myenv\Lib\site-packages\rest_framework\views.py", line 509, in dispatch
    response = self.handle_exception(exc)
               ^^^^^^^^^^^^^^^^^^^^^^^^^^
  File "C:\Users\chanm\OneDrive\Desktop\ERP\backend\myenv\Lib\site-packages\rest_framework\views.py", line 469, in handle_exception
    self.raise_uncaught_exception(exc)
  File "C:\Users\chanm\OneDrive\Desktop\ERP\backend\myenv\Lib\site-packages\rest_framework\views.py", line 480, in raise_uncaught_exception
    raise exc
  File "C:\Users\chanm\OneDrive\Desktop\ERP\backend\myenv\Lib\site-packages\rest_framework\views.py", line 506, in dispatch
    response = handler(request, *args, **kwargs)
               ^^^^^^^^^^^^^^^^^^^^^^^^^^^^^^^^^
  File "C:\Users\chanm\OneDrive\Desktop\ERP\backend\AuthPortal\views\student_views.py", line 62, in post
    token = super().post(request, *args, **kwargs)
            ^^^^^^^^^^^^^^^^^^^^^^^^^^^^^^^^^^^^^^
  File "C:\Users\chanm\OneDrive\Desktop\ERP\backend\myenv\Lib\site-packages\rest_framework_simplejwt\views.py", line 44, in post
    serializer.is_valid(raise_exception=True)
  File "C:\Users\chanm\OneDrive\Desktop\ERP\backend\myenv\Lib\site-packages\rest_framework\serializers.py", line 227, in is_valid
    self._validated_data = self.run_validation(self.initial_data)
                           ^^^^^^^^^^^^^^^^^^^^^^^^^^^^^^^^^^^^^^
  File "C:\Users\chanm\OneDrive\Desktop\ERP\backend\myenv\Lib\site-packages\rest_framework\serializers.py", line 429, in run_validation
    value = self.validate(value)
            ^^^^^^^^^^^^^^^^^^^^
  File "C:\Users\chanm\OneDrive\Desktop\ERP\backend\myenv\Lib\site-packages\rest_framework_simplejwt\serializers.py", line 75, in validate
    refresh = self.get_token(self.user)
              ^^^^^^^^^^^^^^^^^^^^^^^^^
  File "C:\Users\chanm\OneDrive\Desktop\ERP\backend\myenv\Lib\site-packages\rest_framework_simplejwt\serializers.py", line 66, in get_token
    return cls.token_class.for_user(user)  # type: ignore
           ^^^^^^^^^^^^^^^^^^^^^^^^^^^^^^
  File "C:\Users\chanm\OneDrive\Desktop\ERP\backend\myenv\Lib\site-packages\rest_framework_simplejwt\tokens.py", line 203, in for_user
    user_id = getattr(user, api_settings.USER_ID_FIELD)
              ^^^^^^^^^^^^^^^^^^^^^^^^^^^^^^^^^^^^^^^^^
AttributeError: 'User' object has no attribute 'id'
"POST /auth/student/login/ HTTP/1.1" 500 119885
Internal Server Error: /auth/student/login/
Traceback (most recent call last):
  File "C:\Users\chanm\OneDrive\Desktop\ERP\backend\myenv\Lib\site-packages\django\core\handlers\exception.py", line 55, in inner
    response = get_response(request)
               ^^^^^^^^^^^^^^^^^^^^^
  File "C:\Users\chanm\OneDrive\Desktop\ERP\backend\myenv\Lib\site-packages\django\core\handlers\base.py", line 197, in _get_response
    response = wrapped_callback(request, *callback_args, **callback_kwargs)
               ^^^^^^^^^^^^^^^^^^^^^^^^^^^^^^^^^^^^^^^^^^^^^^^^^^^^^^^^^^^^
  File "C:\Users\chanm\OneDrive\Desktop\ERP\backend\myenv\Lib\site-packages\django\views\decorators\csrf.py", line 54, in wrapped_view
    return view_func(*args, **kwargs)
           ^^^^^^^^^^^^^^^^^^^^^^^^^^
  File "C:\Users\chanm\OneDrive\Desktop\ERP\backend\myenv\Lib\site-packages\django\views\generic\base.py", line 103, in view
    return self.dispatch(request, *args, **kwargs)
           ^^^^^^^^^^^^^^^^^^^^^^^^^^^^^^^^^^^^^^^
  File "C:\Users\chanm\OneDrive\Desktop\ERP\backend\myenv\Lib\site-packages\rest_framework\views.py", line 509, in dispatch
    response = self.handle_exception(exc)
               ^^^^^^^^^^^^^^^^^^^^^^^^^^
  File "C:\Users\chanm\OneDrive\Desktop\ERP\backend\myenv\Lib\site-packages\rest_framework\views.py", line 469, in handle_exception
    self.raise_uncaught_exception(exc)
  File "C:\Users\chanm\OneDrive\Desktop\ERP\backend\myenv\Lib\site-packages\rest_framework\views.py", line 480, in raise_uncaught_exception
    raise exc
  File "C:\Users\chanm\OneDrive\Desktop\ERP\backend\myenv\Lib\site-packages\rest_framework\views.py", line 506, in dispatch
    response = handler(request, *args, **kwargs)
               ^^^^^^^^^^^^^^^^^^^^^^^^^^^^^^^^^
  File "C:\Users\chanm\OneDrive\Desktop\ERP\backend\AuthPortal\views\student_views.py", line 64, in post
    token = super().post(request, *args, **kwargs)
            ^^^^^^^^^^^^^^^^^^^^^^^^^^^^^^^^^^^^^^
  File "C:\Users\chanm\OneDrive\Desktop\ERP\backend\myenv\Lib\site-packages\rest_framework_simplejwt\views.py", line 44, in post
    serializer.is_valid(raise_exception=True)
  File "C:\Users\chanm\OneDrive\Desktop\ERP\backend\myenv\Lib\site-packages\rest_framework\serializers.py", line 227, in is_valid
    self._validated_data = self.run_validation(self.initial_data)
                           ^^^^^^^^^^^^^^^^^^^^^^^^^^^^^^^^^^^^^^
  File "C:\Users\chanm\OneDrive\Desktop\ERP\backend\myenv\Lib\site-packages\rest_framework\serializers.py", line 429, in run_validation
    value = self.validate(value)
            ^^^^^^^^^^^^^^^^^^^^
  File "C:\Users\chanm\OneDrive\Desktop\ERP\backend\myenv\Lib\site-packages\rest_framework_simplejwt\serializers.py", line 75, in validate
    refresh = self.get_token(self.user)
              ^^^^^^^^^^^^^^^^^^^^^^^^^
  File "C:\Users\chanm\OneDrive\Desktop\ERP\backend\myenv\Lib\site-packages\rest_framework_simplejwt\serializers.py", line 66, in get_token
    return cls.token_class.for_user(user)  # type: ignore
           ^^^^^^^^^^^^^^^^^^^^^^^^^^^^^^
  File "C:\Users\chanm\OneDrive\Desktop\ERP\backend\myenv\Lib\site-packages\rest_framework_simplejwt\tokens.py", line 203, in for_user
    user_id = getattr(user, api_settings.USER_ID_FIELD)
              ^^^^^^^^^^^^^^^^^^^^^^^^^^^^^^^^^^^^^^^^^
AttributeError: 'User' object has no attribute 'id'
"POST /auth/student/login/ HTTP/1.1" 500 119865
Internal Server Error: /auth/student/login/
Traceback (most recent call last):
  File "C:\Users\chanm\OneDrive\Desktop\ERP\backend\myenv\Lib\site-packages\django\core\handlers\exception.py", line 55, in inner
    response = get_response(request)
               ^^^^^^^^^^^^^^^^^^^^^
  File "C:\Users\chanm\OneDrive\Desktop\ERP\backend\myenv\Lib\site-packages\django\core\handlers\base.py", line 197, in _get_response
    response = wrapped_callback(request, *callback_args, **callback_kwargs)
               ^^^^^^^^^^^^^^^^^^^^^^^^^^^^^^^^^^^^^^^^^^^^^^^^^^^^^^^^^^^^
  File "C:\Users\chanm\OneDrive\Desktop\ERP\backend\myenv\Lib\site-packages\django\views\decorators\csrf.py", line 54, in wrapped_view
    return view_func(*args, **kwargs)
           ^^^^^^^^^^^^^^^^^^^^^^^^^^
  File "C:\Users\chanm\OneDrive\Desktop\ERP\backend\myenv\Lib\site-packages\django\views\generic\base.py", line 103, in view
    return self.dispatch(request, *args, **kwargs)
           ^^^^^^^^^^^^^^^^^^^^^^^^^^^^^^^^^^^^^^^
  File "C:\Users\chanm\OneDrive\Desktop\ERP\backend\myenv\Lib\site-packages\rest_framework\views.py", line 509, in dispatch
    response = self.handle_exception(exc)
               ^^^^^^^^^^^^^^^^^^^^^^^^^^
  File "C:\Users\chanm\OneDrive\Desktop\ERP\backend\myenv\Lib\site-packages\rest_framework\views.py", line 469, in handle_exception
    self.raise_uncaught_exception(exc)
  File "C:\Users\chanm\OneDrive\Desktop\ERP\backend\myenv\Lib\site-packages\rest_framework\views.py", line 480, in raise_uncaught_exception
    raise exc
  File "C:\Users\chanm\OneDrive\Desktop\ERP\backend\myenv\Lib\site-packages\rest_framework\views.py", line 506, in dispatch
    response = handler(request, *args, **kwargs)
               ^^^^^^^^^^^^^^^^^^^^^^^^^^^^^^^^^
  File "C:\Users\chanm\OneDrive\Desktop\ERP\backend\AuthPortal\views\student_views.py", line 64, in post
    token = super().post(request, *args, **kwargs)
            ^^^^^^^^^^^^^^^^^^^^^^^^^^^^^^^^^^^^^^
  File "C:\Users\chanm\OneDrive\Desktop\ERP\backend\myenv\Lib\site-packages\rest_framework_simplejwt\views.py", line 44, in post
    serializer.is_valid(raise_exception=True)
  File "C:\Users\chanm\OneDrive\Desktop\ERP\backend\myenv\Lib\site-packages\rest_framework\serializers.py", line 227, in is_valid
    self._validated_data = self.run_validation(self.initial_data)
                           ^^^^^^^^^^^^^^^^^^^^^^^^^^^^^^^^^^^^^^
  File "C:\Users\chanm\OneDrive\Desktop\ERP\backend\myenv\Lib\site-packages\rest_framework\serializers.py", line 429, in run_validation
    value = self.validate(value)
            ^^^^^^^^^^^^^^^^^^^^
  File "C:\Users\chanm\OneDrive\Desktop\ERP\backend\myenv\Lib\site-packages\rest_framework_simplejwt\serializers.py", line 75, in validate
    refresh = self.get_token(self.user)
              ^^^^^^^^^^^^^^^^^^^^^^^^^
  File "C:\Users\chanm\OneDrive\Desktop\ERP\backend\myenv\Lib\site-packages\rest_framework_simplejwt\serializers.py", line 66, in get_token
    return cls.token_class.for_user(user)  # type: ignore
           ^^^^^^^^^^^^^^^^^^^^^^^^^^^^^^
  File "C:\Users\chanm\OneDrive\Desktop\ERP\backend\myenv\Lib\site-packages\rest_framework_simplejwt\tokens.py", line 203, in for_user
    user_id = getattr(user, api_settings.USER_ID_FIELD)
              ^^^^^^^^^^^^^^^^^^^^^^^^^^^^^^^^^^^^^^^^^
AttributeError: 'User' object has no attribute 'id'
"POST /auth/student/login/ HTTP/1.1" 500 119882
Internal Server Error: /auth/student/login/
Traceback (most recent call last):
  File "C:\Users\chanm\OneDrive\Desktop\ERP\backend\myenv\Lib\site-packages\django\core\handlers\exception.py", line 55, in inner
    response = get_response(request)
               ^^^^^^^^^^^^^^^^^^^^^
  File "C:\Users\chanm\OneDrive\Desktop\ERP\backend\myenv\Lib\site-packages\django\core\handlers\base.py", line 197, in _get_response
    response = wrapped_callback(request, *callback_args, **callback_kwargs)
               ^^^^^^^^^^^^^^^^^^^^^^^^^^^^^^^^^^^^^^^^^^^^^^^^^^^^^^^^^^^^
  File "C:\Users\chanm\OneDrive\Desktop\ERP\backend\myenv\Lib\site-packages\django\views\decorators\csrf.py", line 54, in wrapped_view
    return view_func(*args, **kwargs)
           ^^^^^^^^^^^^^^^^^^^^^^^^^^
  File "C:\Users\chanm\OneDrive\Desktop\ERP\backend\myenv\Lib\site-packages\django\views\generic\base.py", line 103, in view
    return self.dispatch(request, *args, **kwargs)
           ^^^^^^^^^^^^^^^^^^^^^^^^^^^^^^^^^^^^^^^
  File "C:\Users\chanm\OneDrive\Desktop\ERP\backend\myenv\Lib\site-packages\rest_framework\views.py", line 509, in dispatch
    response = self.handle_exception(exc)
               ^^^^^^^^^^^^^^^^^^^^^^^^^^
  File "C:\Users\chanm\OneDrive\Desktop\ERP\backend\myenv\Lib\site-packages\rest_framework\views.py", line 469, in handle_exception
    self.raise_uncaught_exception(exc)
  File "C:\Users\chanm\OneDrive\Desktop\ERP\backend\myenv\Lib\site-packages\rest_framework\views.py", line 480, in raise_uncaught_exception
    raise exc
  File "C:\Users\chanm\OneDrive\Desktop\ERP\backend\myenv\Lib\site-packages\rest_framework\views.py", line 506, in dispatch
    response = handler(request, *args, **kwargs)
               ^^^^^^^^^^^^^^^^^^^^^^^^^^^^^^^^^
  File "C:\Users\chanm\OneDrive\Desktop\ERP\backend\AuthPortal\views\student_views.py", line 64, in post
    token = super().post(request, *args, **kwargs)
            ^^^^^^^^^^^^^^^^^^^^^^^^^^^^^^^^^^^^^^
  File "C:\Users\chanm\OneDrive\Desktop\ERP\backend\myenv\Lib\site-packages\rest_framework_simplejwt\views.py", line 44, in post
    serializer.is_valid(raise_exception=True)
  File "C:\Users\chanm\OneDrive\Desktop\ERP\backend\myenv\Lib\site-packages\rest_framework\serializers.py", line 227, in is_valid
    self._validated_data = self.run_validation(self.initial_data)
                           ^^^^^^^^^^^^^^^^^^^^^^^^^^^^^^^^^^^^^^
  File "C:\Users\chanm\OneDrive\Desktop\ERP\backend\myenv\Lib\site-packages\rest_framework\serializers.py", line 429, in run_validation
    value = self.validate(value)
            ^^^^^^^^^^^^^^^^^^^^
  File "C:\Users\chanm\OneDrive\Desktop\ERP\backend\myenv\Lib\site-packages\rest_framework_simplejwt\serializers.py", line 75, in validate
    refresh = self.get_token(self.user)
              ^^^^^^^^^^^^^^^^^^^^^^^^^
  File "C:\Users\chanm\OneDrive\Desktop\ERP\backend\myenv\Lib\site-packages\rest_framework_simplejwt\serializers.py", line 66, in get_token
    return cls.token_class.for_user(user)  # type: ignore
           ^^^^^^^^^^^^^^^^^^^^^^^^^^^^^^
  File "C:\Users\chanm\OneDrive\Desktop\ERP\backend\myenv\Lib\site-packages\rest_framework_simplejwt\tokens.py", line 203, in for_user
    user_id = getattr(user, api_settings.USER_ID_FIELD)
              ^^^^^^^^^^^^^^^^^^^^^^^^^^^^^^^^^^^^^^^^^
AttributeError: 'User' object has no attribute 'id'
"POST /auth/student/login/ HTTP/1.1" 500 119882
